#VRML_SIM R2025a utf8

EXTERNPROTO "https://raw.githubusercontent.com/cyberbotics/webots/R2025a/projects/objects/backgrounds/protos/TexturedBackground.proto"
EXTERNPROTO "https://raw.githubusercontent.com/cyberbotics/webots/R2025a/projects/objects/backgrounds/protos/TexturedBackgroundLight.proto"
EXTERNPROTO "https://raw.githubusercontent.com/cyberbotics/webots/R2025a/projects/objects/floors/protos/RectangleArena.proto"
EXTERNPROTO "https://raw.githubusercontent.com/cyberbotics/webots/R2025a/projects/objects/animals/protos/Cat.proto"
EXTERNPROTO "https://raw.githubusercontent.com/cyberbotics/webots/R2025a/projects/objects/animals/protos/Dog.proto"

WorldInfo {
}
Viewpoint {
  orientation -0.14223737993416788 0.3473770739908884 0.9268752322804791 0.8319891887821301
  position -8.249658543031163 -8.61875538368159 4.355256028702183
}
TexturedBackground {
  texture "stadium"
}
TexturedBackgroundLight {
}
RectangleArena {
  rotation 0 1 0 5.30716e-06
  floorSize 4 4
}
DEF Obs1 Solid {
  translation -0.0430445 -0.582912 0.133388
  rotation -0.0025754902978973823 0.002671230308971273 0.9999931156654838 -1.5881053071795863
  children [
    Shape {
      appearance PBRAppearance {
      }
      geometry Box {
        size 1 0.05 0.5
      }
    }
  ]
}
Robot {
  translation -1.633168527633221 -1.6762622039328732 0.03986348739797408
  rotation 0.0014175245229881906 0.0011694277511180816 0.9999983115300555 3.1024364299574785
  children [
    DEF gps GPS {
      translation -0.05 -0.02 0.03
      children [
        Shape {
          appearance PBRAppearance {
          }
          geometry Cylinder {
            height 0.02
            radius 0.02
          }
        }
      ]
      boundingObject Shape {
        appearance PBRAppearance {
        }
        geometry Cylinder {
          height 0.02
          radius 0.02
        }
      }
      physics Physics {
      }
    }
    DEF lidar Lidar {
      translation 0.07 -0.02 0.04
      children [
        Shape {
          appearance PBRAppearance {
          }
          geometry Cylinder {
            height 0.025
            radius 0.025
          }
        }
      ]
      boundingObject Shape {
        appearance PBRAppearance {
        }
        geometry Cylinder {
          height 0.025
          radius 0.025
        }
      }
      physics Physics {
      }
      horizontalResolution 128
      fieldOfView 3.14
      verticalFieldOfView 0.1
      numberOfLayers 1
    }
    DEF BODY Shape {
      appearance PBRAppearance {
        baseColor 0.917647 0.145098 0.145098
        roughness 1
        metalness 0
      }
      geometry Box {
        size 0.2 0.1 0.05
      }
    }
    DEF WHEEL1 HingeJoint {
      jointParameters HingeJointParameters {
        position 33432.55111761546
        axis 0 1 0
        anchor 0.05 0.06 0
      }
      device [
        RotationalMotor {
          name "wheel1"
        }
      ]
      endPoint Solid {
        translation 0.04932377501213003 0.06043224674532349 -0.0006058666435857
        rotation -0.9813720892536445 0.13814180288993597 -0.13351278863185792 4.672767244532193
        children [
          DEF WHEEL Shape {
            appearance PBRAppearance {
              baseColor 0.305882 0.898039 0.25098
              roughness 1
              metalness 0
            }
            geometry Cylinder {
              height 0.02
              radius 0.04
              subdivision 24
            }
          }
        ]
        boundingObject USE WHEEL
        physics Physics {
        }
        linearVelocity -3.08391816794936e-10 3.4538663381586447e-10 3.691774374208346e-08
        angularVelocity -1.111012656664876e-09 -2.8718667986960713e-08 -3.090101464809009e-09
      }
    }
    DEF WHEEL2 HingeJoint {
      jointParameters HingeJointParameters {
        position 28917.47527976763
        axis 0 1 0
        anchor 0.05 -0.06 0
      }
      device [
        RotationalMotor {
          name "wheel2"
        }
      ]
      endPoint Solid {
        translation 0.050002219179531626 -0.06000008469764562 -8.073828956452417e-08
        rotation -0.31773210562651144 -0.6704636381887283 0.6704661206361415 3.756879202309581
        children [
          USE WHEEL
        ]
        name "solid(1)"
        boundingObject USE WHEEL
        physics Physics {
        }
        linearVelocity 8.172644854723597e-11 5.679925747645556e-11 6.922673539769295e-09
        angularVelocity -3.2635529348513145e-11 2.983920237496514e-09 -3.1661080000321258e-09
      }
    }
    DEF WHEEL3 HingeJoint {
      jointParameters HingeJointParameters {
        position 33432.55092248376
        axis 0 1 0
        anchor -0.05 0.06 0
      }
      device [
        RotationalMotor {
          name "wheel3"
        }
      ]
      endPoint Solid {
        translation -0.05000462190588916 0.060000084994313085 4.442251006289079e-07
        rotation 0.9809708883888757 -0.13728795541868002 0.13728850436398013 1.590011330205451
        children [
          USE WHEEL
        ]
        name "solid(2)"
        boundingObject USE WHEEL
        physics Physics {
        }
        linearVelocity -2.0918517706485032e-10 -1.671515941248537e-10 5.733366324643507e-09
        angularVelocity -3.223726423918088e-11 2.9076987536383087e-09 -3.1659259693010387e-09
      }
    }
    DEF WHEEL4 HingeJoint {
      jointParameters HingeJointParameters {
        position 28917.47419620305
        axis 0 1 0
        anchor -0.05 -0.06 0
      }
      device [
        RotationalMotor {
          name "wheel4"
        }
      ]
      endPoint Solid {
        translation -0.04999790726329771 -0.05999991499841628 2.0316955196555985e-07
        rotation -0.3181320407200003 -0.6703688052738648 0.670371292332107 3.7576056422480644
        children [
          USE WHEEL
        ]
        name "solid(3)"
        boundingObject USE WHEEL
        physics Physics {
        }
        linearVelocity 3.3696635999423876e-11 -1.8698047014782287e-10 3.361723649050824e-08
        angularVelocity -2.977047599531018e-11 3.0507428959886797e-09 -3.166268802631668e-09
      }
    }
    DEF DS_RIGHT DistanceSensor {
      translation 0.1 -0.03 0
      rotation 0 0 1 -0.3
      children [
        Shape {
          appearance PBRAppearance {
            baseColor 0.184314 0.596078 0.847059
            roughness 1
            metalness 0
          }
          geometry Box {
            size 0.01 0.01 0.01
          }
        }
      ]
      name "ds_right"
    }
    DEF DS_LEFT DistanceSensor {
      translation 0.1 0.03 0
      rotation 0 0 1 0.3
      children [
        Shape {
          appearance PBRAppearance {
            baseColor 0.184314 0.596078 0.847059
            roughness 1
            metalness 0
          }
          geometry Box {
            size 0.01 0.01 0.01
          }
        }
      ]
      name "ds_left"
    }
  ]
  boundingObject USE BODY
  physics Physics {
    density -1
    mass 1
  }
  controller "controlador"
  window "<none>"
}
Solid {
  translation 0 -1.6 0
  children [
    Dog {
      translation 0 1.86 0
      scale 0.75
    }
  ]
  name "solid(4)"
}
Solid {
  translation 1.74 1.51 0
  rotation 0 0 1 1.5708
  children [
    Shape {
      appearance PBRAppearance {
      }
      geometry Box {
        size 0.9 0.05 0.6
      }
    }
  ]
  name "solid(1)"
}
Solid {
  translation -0.08 -0.08 0.09
  children [
    Shape {
      appearance PBRAppearance {
      }
      geometry Box {
        size 2 0.05 0.6
      }
    }
  ]
  name "solid(2)"
}
Solid {
  translation 1.76 -2.07 0
  children [
    Cat {
      translation 0 1.69 0
    }
    Shape {
      appearance PBRAppearance {
      }
      geometry Box {
        size 0.1 0.1 0.1
      }
    }
  ]
  name "solid(3)"
}
